[2024-11-08T10:17:36.090+0000] {taskinstance.py:1979} INFO - Dependencies all met for dep_context=non-requeueable deps ti=<TaskInstance: etl_csv_file.send_data_to_elastich_search manual__2024-11-08T10:17:18.042149+00:00 [queued]>
[2024-11-08T10:17:36.124+0000] {taskinstance.py:1979} INFO - Dependencies all met for dep_context=requeueable deps ti=<TaskInstance: etl_csv_file.send_data_to_elastich_search manual__2024-11-08T10:17:18.042149+00:00 [queued]>
[2024-11-08T10:17:36.126+0000] {taskinstance.py:2193} INFO - Starting attempt 1 of 1
[2024-11-08T10:17:36.480+0000] {taskinstance.py:2217} INFO - Executing <Task(_PythonDecoratedOperator): send_data_to_elastich_search> on 2024-11-08 10:17:18.042149+00:00
[2024-11-08T10:17:36.489+0000] {standard_task_runner.py:60} INFO - Started process 200 to run task
[2024-11-08T10:17:36.497+0000] {standard_task_runner.py:87} INFO - Running: ['airflow', 'tasks', 'run', 'etl_csv_file', 'send_data_to_elastich_search', 'manual__2024-11-08T10:17:18.042149+00:00', '--job-id', '13', '--raw', '--subdir', 'DAGS_FOLDER/etl_csv_file.py', '--cfg-path', '/tmp/tmpdj2d364a']
[2024-11-08T10:17:36.505+0000] {standard_task_runner.py:88} INFO - Job 13: Subtask send_data_to_elastich_search
[2024-11-08T10:17:36.614+0000] {task_command.py:423} INFO - Running <TaskInstance: etl_csv_file.send_data_to_elastich_search manual__2024-11-08T10:17:18.042149+00:00 [running]> on host efe6839ec606
[2024-11-08T10:17:36.937+0000] {taskinstance.py:2513} INFO - Exporting env vars: AIRFLOW_CTX_DAG_OWNER='Satrio' AIRFLOW_CTX_DAG_ID='etl_csv_file' AIRFLOW_CTX_TASK_ID='send_data_to_elastich_search' AIRFLOW_CTX_EXECUTION_DATE='2024-11-08T10:17:18.042149+00:00' AIRFLOW_CTX_TRY_NUMBER='1' AIRFLOW_CTX_DAG_RUN_ID='manual__2024-11-08T10:17:18.042149+00:00'
[2024-11-08T10:17:37.215+0000] {taskinstance.py:2731} ERROR - Task failed with exception
Traceback (most recent call last):
  File "/home/airflow/.local/lib/python3.8/site-packages/airflow/models/taskinstance.py", line 444, in _execute_task
    result = _execute_callable(context=context, **execute_callable_kwargs)
  File "/home/airflow/.local/lib/python3.8/site-packages/airflow/models/taskinstance.py", line 414, in _execute_callable
    return execute_callable(context=context, **execute_callable_kwargs)
  File "/home/airflow/.local/lib/python3.8/site-packages/airflow/decorators/base.py", line 241, in execute
    return_value = super().execute(context)
  File "/home/airflow/.local/lib/python3.8/site-packages/airflow/operators/python.py", line 200, in execute
    return_value = self.execute_callable()
  File "/home/airflow/.local/lib/python3.8/site-packages/airflow/operators/python.py", line 217, in execute_callable
    return self.python_callable(*self.op_args, **self.op_kwargs)
  File "/opt/airflow/dags/etl_csv_file.py", line 100, in send_data_to_elastich_search
    helpers.bulk(es, actions)
NameError: name 'helpers' is not defined
[2024-11-08T10:17:37.233+0000] {taskinstance.py:1149} INFO - Marking task as FAILED. dag_id=etl_csv_file, task_id=send_data_to_elastich_search, execution_date=20241108T101718, start_date=20241108T101736, end_date=20241108T101737
[2024-11-08T10:17:37.256+0000] {standard_task_runner.py:107} ERROR - Failed to execute job 13 for task send_data_to_elastich_search (name 'helpers' is not defined; 200)
[2024-11-08T10:17:37.274+0000] {local_task_job_runner.py:234} INFO - Task exited with return code 1
[2024-11-08T10:17:37.325+0000] {taskinstance.py:3312} INFO - 0 downstream tasks scheduled from follow-on schedule check
